Workbook
Name Nombre_empresa: #REF!

Sheet ProForma
A19: PROFORMA
A22: Supply Chain Consulting
A23: Presidente Miguel Alemán Valdez 904, desp 201 | C23: Cliente: Compañía AHT Cooling Systems de México, S.A. de C.V.
A24: Nápoles, Benito Juárez, Ciudad de México. C.P. 03180 | C24: Fecha: 01 al 31 de Enero de 2025
A25: RFC: SCC1202278VA | C25: Tipo de Servicio: Integral
A26: Cantidad | B26: Descripción | C26: Costo Unitario | D26: Costo Total
A27: 700 | B27: Almacenaje | C27: 103320 | D27: =Table_Items4[[#This Row],[Costo Unitario]] -> 103320
A28: =Resumen!AE9 -> 1595.8226 | B28: Almacenaje adicional | C28: 170 | D28: =Table_Items4[[#This Row],[Costo Unitario]]*Table_Items4[[#This Row],[Cantidad]] -> 271289.84
A29: =Resumen!AE10 -> 523 | B29: Entradas | C29: 78.5 | D29: =Table_Items4[[#This Row],[Costo Unitario]]*Table_Items4[[#This Row],[Cantidad]] -> 41055.5
A30: =Resumen!AE11 -> 135 | B30: Salidas | C30: 78.5 | D30: =Table_Items4[[#This Row],[Costo Unitario]]*Table_Items4[[#This Row],[Cantidad]] -> 10597.5
A31: =Resumen!AE12 -> 5 | B31: Pruebas | C31: 73.5 | D31: =Table_Items4[[#This Row],[Costo Unitario]]*Table_Items4[[#This Row],[Cantidad]] -> 367.5
A32: 3 | B32: Envíos por paquetería | C32: =Resumen!T20 -> 4298 | D32: =Table_Items4[[#This Row],[Costo Unitario]] -> 4298
A33: =Resumen!AE22 -> 0 | B33: Reparaciones | C33: 265 | D33: =Table_Items4[[#This Row],[Costo Unitario]]*Table_Items4[[#This Row],[Cantidad]] -> 0
A34: =Resumen!AE21 -> 42 | B34: Servicios adicionales | C34: 78.5 | D34: =Table_Items4[[#This Row],[Costo Unitario]]*Table_Items4[[#This Row],[Cantidad]] -> 3297
A35: =Resumen!P28+Resumen!P29 -> 4 | B35: Hora extra (L-V) | C35: 1500 | D35: =Table_Items4[[#This Row],[Costo Unitario]]*Table_Items4[[#This Row],[Cantidad]] -> 6000
A36: =Resumen!P27 -> 4 | B36: Hora extra (Sábado) | C36: 3000 | D36: =Table_Items4[[#This Row],[Costo Unitario]]*Table_Items4[[#This Row],[Cantidad]] -> 12000
A37: 0 | B37: Hora extra (Domingo) | C37: 4600 | D37: =Table_Items4[[#This Row],[Costo Unitario]]*Table_Items4[[#This Row],[Cantidad]] -> 0
C38: Subtotal | D38: =SUM(Table_Items4[[Costo Total ]]) -> 452225.34
C39: IVA | D39: =D38*0.16 -> 72356.054
C40: Retención (4%)
C41: Total | D41: =D38+D39-D40 -> 524581.39

Sheet Resumen
A1: CONCEPTO | B1: 45566 | C1: 45567 | D1: 45568 | E1: 45569 | F1: 45570 | G1: 45571 | H1: 45572 | I1: 45573 | J1: 45574 | K1: 45575 | L1: 45576 | M1: 45577 | N1: 45578 | O1: 45579 | P1: 45580 | Q1: 45581 | R1: 45582 | S1: 45583 | T1: 45584 | U1: 45585 | V1: 45586 | W1: 45587 | X1: 45588 | Y1: 45589 | Z1: 45590 | AA1: 45591 | AB1: 45592 | AC1: 45593 | AD1: 29 | AE1: 30 | AF1: 31 | AG1: TOTALES
A2: ENTRADAS | B2: 0 | C2: =35+35 -> 70 | D2: 10 | E2: 0 | F2: 0 | G2: 0 | H2: 0 | I2: 0 | J2: 0 | K2: 0 | L2: 0 | M2: 5* | N2: =35+14 -> 49 | O2: =18+34 -> 52 | P2: 0 | Q2: 0 | R2: 0 | S2: 0 | T2: 0 | U2: 0 | V2: 0 | W2: 0 | X2: =38+38+38 -> 114 | Y2: 0 | Z2: 0 | AA2: =38+38+38+38+38+38 -> 228 | AB2: 0 | AC2: 0 | AD2: 0 | AE2: 0 | AF2: 0 | AG2: =SUM(B2:AF2) -> 523
A3: SALIDAS | B3: 0 | C3: 4 | D3: 0 | E3: 0 | F3: 0 | G3: 0 | H3: 0 | I3: 1 | J3: 0 | K3: 0 | L3: 0 | M3: =6+6+1 -> 13 | N3: 0 | O3: =8 -> 8 | P3: 8 | Q3: =27+3+8 -> 38 | R3: 0 | S3: 0 | T3: 0 | U3: 0 | V3: =3+10 -> 13 | W3: 0 | X3: =9+6 -> 15 | Y3: 0 | Z3: 0 | AA3: =3 -> 3 | AB3: =6+2 -> 8 | AC3: =24 -> 24 | AD3: 0 | AE3: 0 | AF3: 0 | AG3: =SUM(B3:AF3) -> 135
E7: .
A8: ENTRADAS | J8: ENVIO DE REFACCIONES | X8: DESGLOSE DE SERVICIOS
A9: FECHA | B9: REF SCC | C9: EQUIPOS | J9: FECHA | L9: REF SCC | N9: PAQUETERÍA | P9: REFACCIÓN ENVIADA | R9: DESTINO | T9: COSTO | X9: PROMEDIO POSICIONES | AE9: ='Desglose '!AK31-ProForma!A27-830 -> 1595.8226
X10: ENTRADAS | AE10: =AG2 -> 523
A11: 46024 | B11: SCAHT030058 | C11: 35 | J11: 46029 | L11: SCAHT030062 | N11: ESTAFETA | P11: COMPRESOR Y TARJETA LÓGICA | R11: QUERÉTARO | T11: 1290 | X11: SALIDAS | AE11: =AG3 -> 135
A12: 46024 | B12: SCAHT030059 | C12: 35 | J12: 46045 | L12: SCAHT030082 | N12: ESTAFETA | P12: 3 TIRAS LED | R12: VERACRUZ | T12: 1258 | X12: PRUEBAS | AE12: 5
A13: 46025 | B13: SCAHT030060 | C13: 10 | J13: 46050 | L13: SCAHT030085 | N13: FEDEX | P13: COMPRESOR Y TARJETA LÓGICA | R13: OAXACA | T13: 1750 | X13: COLOCAR EQUIPOS EN PISO | AE13: 4
A14: 46034 | B14: SCAHT030066 | C14: 5* | F14: pallets | X14: APERTURA DE EQUIPOS PARA REVISIÓN | AE14: 4
A15: 46035 | B15: SCAHT030067 | C15: 35 | X15: CAMBIO DE REJILLAS | AE15: 26
A16: 46035 | B16: SCAHT030068 | C16: 14 | X16: CAMBIO DE CABLES | AE16: 0 | AO16: º
A17: 46036 | B17: SCAHT030069 | C17: 34 | X17: LIMPIEZA DE EQUIPOS | AE17: 0
A18: 46036 | B18: SCAHT030070 | C18: 18 | X18: TORNILLOS SUELTOS TAPA DIFUSOR | AE18: 0
A19: 46045 | B19: SCAHT030073 | C19: 38 | X19: HORAS EXTRA | AE19: 8
A20: 46045 | B20: SCAHT030074 | C20: 38 | R20: TOTAL | T20: =SUM(T11:U19) -> 4298 | X20: INVENTARIO | AE20: 0
A21: 46045 | B21: SCAHT030075 | C21: 38 | X21: TOTAL SERVICIOS ADICIONALES | AE21: =SUM(AE13:AG20) -> 42
A22: 46048 | B22: SCAHT030076 | C22: 38 | X22: TOTAL REPARACIONES MEMO | AE22: 0
A23: 46048 | B23: SCAHT030077 | C23: 38
A24: 46048 | B24: SCAHT030078 | C24: 38 | J24: TIEMPO EXTRA
A25: 46048 | B25: SCAHT030079 | C25: 38 | J25: FECHA | L25: HORA INICIO | N25: HORA TÉRMINO | P25: TOTAL HORAS | R25: COSTO UNITARIO | T25: COSTO TOTAL
A26: 46048 | B26: SCAHT030080 | C26: 38
A27: 46048 | B27: SCAHT030081 | C27: 38 | J27: 46025 | L27: 8 | N27: 12 | P27: 4 | R27: 3000 | T27: =R27*P27 -> 12000
B28: TOTAL | C28: =SUM(C11:E27) -> 523 | J28: 46037 | L28: 6 | N28: 8 | P28: 2 | R28: 1500 | T28: =R28*P28 -> 3000
J29: 46048 | L29: 6 | N29: 8 | P29: 2 | R29: 1500 | T29: =R29*P29 -> 3000
T30: =R30*P30 -> 0
T31: =R31*P31 -> 0
A32: SALIDAS | T32: =R32*P32 -> 0
A33: FECHA | B33: REF SCC | C33: EQUIPOS | T33: =R33*P33 -> 0
T34: =R34*P34 -> 0
A35: 46024 | B35: SCCASI080281 | C35: 4 | T35: =R35*P35 -> 0
A36: 46030 | B36: SCAHT030063 | C36: 1 | R36: TOTAL | T36: =+SUM(T27:U35) -> 18000
A37: 46034 | B37: SCCASI080284 | C37: 6
A38: 46034 | B38: SCCASI080285 | C38: 6
A39: 46034 | B39: SCCASI080286 | C39: 1
A40: 46036 | B40: SCCASI080287 | C40: 8
A41: 46037 | B41: SCAHT030064 | C41: 8
A42: 46038 | B42: SCAHT030065 | C42: 27
A43: 46038 | B43: SCCASI080288 | C43: 3
...

Sheet Desglose 
B1: MODELO | C1: N°DE EQUIPOS | D1: FACTOR | E1: 1 | F1: 2 | G1: 3 | H1: 4 | I1: 5 | J1: 6 | K1: 7 | L1: 8 | M1: 9 | N1: 10 | O1: 11 | P1: 12 | Q1: 13 | R1: 14 | S1: 15 | T1: 16 | U1: 17 | V1: 18 | W1: 19 | X1: 20 | Y1: 21 | Z1: 22 | AA1: 23 | AB1: 24 | AC1: 25 | AD1: 26 | AE1: 27 | AF1: 28 | AG1: 29 | AH1: 30 | AI1: 31 | AJ1: Promedio mensual | AK1: Promedio mensual
B2: PARIS 250 (-) | C2: 78 | D2: 2 | E2: 47 | F2: =+E2 -> 47 | G2: =+F2 -> 47 | H2: =+G2 -> 47 | I2: =+H2 -> 47 | J2: =+I2 -> 47 | K2: =+J2 -> 47 | L2: =+K2 -> 47 | M2: =+L2 -> 47 | ... AI2: =+AH2 -> 47 | AJ2: =AVERAGE(E2:AI2) -> 47 | AK2: =+AJ2*D2 -> 94
B3: PARIS 250 (MEX) | C3: 46 | D3: 2 | E3: 46 | F3: =+E3 -> 46 | G3: =+F3 -> 46 | H3: =+G3 -> 46 | I3: =+H3 -> 46 | J3: =+I3 -> 46 | K3: =+J3 -> 46 | L3: =+K3 -> 46 | M3: =+L3 -> 46 | ... S3: =+R3 -> 46 | T3: =+S3-6 -> 40 | U3: =+T3 -> 40 | V3: =+U3 -> 40 | W3: =+V3 -> 40 | X3: =+W3 -> 40 | Y3: =+X3 -> 40 | Z3: =+Y3 -> 40 | AA3: =+Z3 -> 40 | AB3: =+AA3 -> 40 | ... AG3: =+AF3 -> 40 | AH3: =+AF3 -> 40 | AI3: =+AG3 -> 40 | AJ3: =AVERAGE(E3:AI3) -> 42.903226 | AK3: =+AJ3*D3 -> 85.806452
B4: PARIS 250 (U) | C4: 1 | D4: 2 | E4: 1 | F4: =+E4 -> 1 | G4: =+F4 -> 1 | H4: =+G4 -> 1 | I4: =+H4 -> 1 | J4: =+I4 -> 1 | K4: =+J4 -> 1 | L4: =+K4 -> 1 | M4: =+L4 -> 1 | ... AG4: =+AF4 -> 1 | AH4: =+AF4 -> 1 | AI4: =+AG4 -> 1 | AJ4: =AVERAGE(E4:AI4) -> 1 | AK4: =+AJ4*D4 -> 2
B5: PARIS 210 (-) | C5: 657 | D5: 2 | E5: 730 | F5: =E5+35+35-4 -> 796 | G5: =F5+10 -> 806 | H5: =G5 -> 806 | I5: =H5 -> 806 | J5: =I5 -> 806 | K5: =J5 -> 806 | L5: =K5-1 -> 805 | M5: =L5 -> 805 | N5: =M5 -> 805 | O5: =N5 -> 805 | P5: =O5-6-6-1 -> 792 | Q5: =P5+35 -> 827 | R5: =Q5+32-8 -> 851 | S5: =R5 -> 851 | T5: =S5-15-3-8 -> 825 | U5: =T5 -> 825 | V5: =U5 -> 825 | W5: =V5 -> 825 | X5: =W5 -> 825 | Y5: =X5-10-3 -> 812 | Z5: =Y5 -> 812 | AA5: =Z5+38+38+38-9-6 -> 911 | AB5: =AA5 -> 911 | AC5: =AB5 -> 911 | AD5: =AC5+38+38+38+38+38+38-3 -> 1136 | AE5: =AD5-6-2 -> 1128 | AF5: =AE5-24 -> 1104 | AG5: =AF5 -> 1104 | AH5: =AG5 -> 1104 | AI5: =AH5 -> 1104 | AJ5: =AVERAGE(E5:AI5) -> 879.32258 | AK5: =+AJ5*D5 -> 1758.6452
B6: PARIS 210 (U) | C6: 30 | D6: 2 | E6: 27 | F6: =+E6 -> 27 | G6: =+F6 -> 27 | H6: =+G6 -> 27 | I6: =+H6 -> 27 | J6: =+I6 -> 27 | K6: =+J6 -> 27 | L6: =+K6 -> 27 | M6: =+L6 -> 27 | ... T6: =+S6 -> 27 | U6: =T6 -> 27 | V6: =+U6 -> 27 | W6: =+V6 -> 27 | X6: =+W6 -> 27 | Y6: =+X6 -> 27 | Z6: =+Y6 -> 27 | AA6: =+Z6 -> 27 | AB6: =+AA6 -> 27 | AC6: =+AB6 -> 27 | ... AG6: =+AF6 -> 27 | AH6: =+AF6 -> 27 | AI6: =+AG6 -> 27 | AJ6: =AVERAGE(E6:AI6) -> 27 | AK6: =+AJ6*D6 -> 54
B7: PARIS 210 (MEX) | C7: 46 | D7: 2 | E7: 42 | F7: =+E7 -> 42 | G7: =+F7 -> 42 | H7: =+G7 -> 42 | I7: =+H7 -> 42 | J7: =+I7 -> 42 | K7: =+J7 -> 42 | L7: =+K7 -> 42 | M7: =+L7 -> 42 | ... AG7: =+AF7 -> 42 | AH7: =+AF7 -> 42 | AI7: =+AG7 -> 42 | AJ7: =AVERAGE(E7:AI7) -> 42 | AK7: =+AJ7*D7 -> 84
B8: Paris 185 (-) L | C8: 86 | D8: 1.5 | E8: 58 | F8: =+E8 -> 58 | G8: =+F8 -> 58 | H8: =+G8 -> 58 | I8: =+H8 -> 58 | J8: =+I8 -> 58 | K8: =+J8 -> 58 | L8: =+K8 -> 58 | M8: =+L8 -> 58 | ... AA8: =+Z8 -> 58 | AB8: =+AA8-1 -> 57 | AC8: =+AB8 -> 57 | AD8: =+AC8 -> 57 | AE8: =+AD8 -> 57 | AF8: =+AE8 -> 57 | AG8: =+AF8 -> 57 | AH8: =+AF8 -> 57 | AI8: =+AG8 -> 57 | AJ8: =AVERAGE(E8:AI8) -> 57.741935 | AK8: =+AJ8*D8 -> 86.612903
B9: Paris 185 (MEX) | C9: 3 | D9: 1.5 | E9: 2 | F9: =+E9 -> 2 | G9: =+F9 -> 2 | H9: =+G9 -> 2 | I9: =+H9 -> 2 | J9: =+I9 -> 2 | K9: =+J9 -> 2 | L9: =+K9 -> 2 | M9: =+L9 -> 2 | ... P9: =+O9 -> 2 | Q9: =+P9+8 -> 10 | R9: =+Q9+2 -> 12 | S9: =+R9 -> 12 | T9: =+S9-5 -> 7 | U9: =+T9 -> 7 | V9: =+U9 -> 7 | W9: =+V9 -> 7 | X9: =+W9 -> 7 | Y9: =+X9 -> 7 | Z9: =+Y9 -> 7 | AA9: =+Z9 -> 7 | AB9: =+AA9 -> 7 | ... AG9: =+AF9 -> 7 | AH9: =+AF9 -> 7 | AI9: =+AG9 -> 7 | AJ9: =AVERAGE(E9:AI9) -> 5.483871 | AK9: =+AJ9*D9 -> 8.2258065
B10: Paris 185 (U) L | C10: 10 | D10: 1.5 | E10: 10 | F10: =+E10 -> 10 | G10: =+F10 -> 10 | H10: =+G10 -> 10 | I10: =+H10 -> 10 | J10: =+I10 -> 10 | K10: =+J10 -> 10 | L10: =+K10 -> 10 | M10: =+L10 -> 10 | ... AG10: =+AF10 -> 10 | AH10: =+AF10 -> 10 | AI10: =+AG10 -> 10 | AJ10: =AVERAGE(E10:AI10) -> 10 | AK10: =+AJ10*D10 -> 15
B11: KYNLEY 210 | C11: 85 | D11: 2 | E11: 72 | F11: =+E11 -> 72 | G11: =+F11 -> 72 | H11: =+G11 -> 72 | I11: =+H11 -> 72 | J11: =+I11 -> 72 | K11: =+J11 -> 72 | L11: =+K11 -> 72 | M11: =+L11 -> 72 | ... R11: =+Q11 -> 72 | S11: =+R11-2 -> 70 | T11: =+S11-1 -> 69 | U11: =+T11 -> 69 | V11: =+U11 -> 69 | W11: =+V11 -> 69 | X11: =+W11 -> 69 | Y11: =+X11 -> 69 | Z11: =+Y11 -> 69 | AA11: =+Z11 -> 69 | AB11: =+AA11 -> 69 | ... AG11: =+AF11 -> 69 | AH11: =+AF11 -> 69 | AI11: =+AG11 -> 69 | AJ11: =AVERAGE(E11:AI11) -> 70.387097 | AK11: =+AJ11*D11 -> 140.77419
B12: KYNLEY 250 | C12: 127 | D12: 2.5 | E12: 123 | F12: =+E12 -> 123 | G12: =+F12 -> 123 | H12: =+G12 -> 123 | I12: =+H12 -> 123 | J12: =+I12 -> 123 | K12: =+J12 -> 123 | L12: =+K12 -> 123 | M12: =+L12 -> 123 | ... P12: =+O12 -> 123 | Q12: =+P12+6 -> 129 | R12: =+Q12 -> 129 | S12: =+R12-6 -> 123 | T12: =+S12 -> 123 | U12: =+T12 -> 123 | V12: =+U12 -> 123 | W12: =+V12 -> 123 | X12: =+W12 -> 123 | Y12: =+X12 -> 123 | Z12: =+Y12 -> 123 | AA12: =+Z12 -> 123 | ... AG12: =+AF12 -> 123 | AH12: =+AF12 -> 123 | AI12: =+AG12 -> 123 | AJ12: =AVERAGE(E12:AI12) -> 123.3871 | AK12: =+AJ12*D12 -> 308.46774
B13: MALTA 185 (U) | C13: 30 | D13: 2 | E13: 30 | F13: =+E13 -> 30 | G13: =+F13 -> 30 | H13: =+G13 -> 30 | I13: =+H13 -> 30 | J13: =+I13 -> 30 | K13: =+J13 -> 30 | L13: =+K13 -> 30 | M13: =+L13 -> 30 | ... AG13: =+AF13 -> 30 | AH13: =+AF13 -> 30 | AI13: =+AG13 -> 30 | AJ13: =AVERAGE(E13:AI13) -> 30 | AK13: =+AJ13*D13 -> 60
B14: Malta 185 (-) L | C14: 0 | D14: 2 | E14: 0 | F14: =+E14 -> 0 | G14: =+F14 -> 0 | H14: =+G14 -> 0 | I14: =+H14 -> 0 | J14: =+I14 -> 0 | K14: =+J14 -> 0 | L14: =+K14 -> 0 | M14: =+L14 -> 0 | ... AG14: =+AF14 -> 0 | AH14: =+AF14 -> 0 | AI14: =+AG14 -> 0 | AJ14: =AVERAGE(E14:AI14) -> 0 | AK14: =+AJ14*D14 -> 0
B15: Malta 145 (U) L | C15: 6 | D15: 2 | E15: 5 | F15: =+E15 -> 5 | G15: =+F15 -> 5 | H15: =+G15 -> 5 | I15: =+H15 -> 5 | J15: =+I15 -> 5 | K15: =+J15 -> 5 | L15: =+K15 -> 5 | M15: =+L15 -> 5 | ... AG15: =+AF15 -> 5 | AH15: =+AF15 -> 5 | AI15: =+AG15 -> 5 | AJ15: =AVERAGE(E15:AI15) -> 5 | AK15: =+AJ15*D15 -> 10
B16: RIO S 68 | C16: 21 | D16: 1 | E16: 20 | F16: =+E16 -> 20 | G16: =+F16 -> 20 | H16: =+G16 -> 20 | I16: =+H16 -> 20 | J16: =+I16 -> 20 | K16: =+J16 -> 20 | L16: =+K16 -> 20 | M16: =+L16 -> 20 | ... AG16: =+AF16 -> 20 | AH16: =+AF16 -> 20 | AI16: =+AG16 -> 20 | AJ16: =AVERAGE(E16:AI16) -> 20 | AK16: =+AJ16*D16 -> 20
B17: RIO S 100 | C17: 13 | D17: 1 | E17: 13 | F17: =+E17 -> 13 | G17: =+F17 -> 13 | H17: =+G17 -> 13 | I17: =+H17 -> 13 | J17: =+I17 -> 13 | K17: =+J17 -> 13 | L17: =+K17 -> 13 | M17: =+L17 -> 13 | ... AG17: =+AF17 -> 13 | AH17: =+AF17 -> 13 | AI17: =+AG17 -> 13 | AJ17: =AVERAGE(E17:AI17) -> 13 | AK17: =+AJ17*D17 -> 13
B18: RIO S 125 | C18: 0 | D18: 1 | E18: 0 | F18: =+E18 -> 0 | G18: =+F18 -> 0 | H18: =+G18 -> 0 | I18: =+H18 -> 0 | J18: =+I18 -> 0 | K18: =+J18 -> 0 | L18: =+K18 -> 0 | M18: =+L18 -> 0 | ... AG18: =+AF18 -> 0 | AH18: =+AF18 -> 0 | AI18: =+AG18 -> 0 | AJ18: =AVERAGE(E18:AI18) -> 0 | AK18: =+AJ18*D18 -> 0
B19: AC XL | C19: 18 | D19: 2 | E19: 18 | F19: =+E19 -> 18 | G19: =+F19 -> 18 | H19: =+G19 -> 18 | I19: =+H19 -> 18 | J19: =+I19 -> 18 | K19: =+J19 -> 18 | L19: =+K19 -> 18 | M19: =+L19 -> 18 | ... AG19: =+AF19 -> 18 | AH19: =+AF19 -> 18 | AI19: =+AG19 -> 18 | AJ19: =AVERAGE(E19:AI19) -> 18 | AK19: =+AJ19*D19 -> 36
B20: AC W | C20: 2 | D20: 1.5 | E20: 2 | F20: =+E20 -> 2 | G20: =+F20 -> 2 | H20: =+G20 -> 2 | I20: =+H20 -> 2 | J20: =+I20 -> 2 | K20: =+J20 -> 2 | L20: =+K20 -> 2 | M20: =+L20 -> 2 | ... AG20: =+AF20 -> 2 | AH20: =+AF20 -> 2 | AI20: =+AG20 -> 2 | AJ20: =AVERAGE(E20:AI20) -> 2 | AK20: =+AJ20*D20 -> 3
B21: AC M | C21: 4 | D21: 2 | E21: 4 | F21: =+E21 -> 4 | G21: =+F21 -> 4 | H21: =+G21 -> 4 | I21: =+H21 -> 4 | J21: =+I21 -> 4 | K21: =+J21 -> 4 | L21: =+K21 -> 4 | M21: =+L21 -> 4 | ... AG21: =+AF21 -> 4 | AH21: =+AF21 -> 4 | AI21: =+AG21 -> 4 | AJ21: =AVERAGE(E21:AI21) -> 4 | AK21: =+AJ21*D21 -> 8
B22: AC S | C22: 10 | D22: 1.5 | E22: 10 | F22: =+E22 -> 10 | G22: =+F22 -> 10 | H22: =+G22 -> 10 | I22: =+H22 -> 10 | J22: =+I22 -> 10 | K22: =+J22 -> 10 | L22: =+K22 -> 10 | M22: =+L22 -> 10 | ... AG22: =+AF22 -> 10 | AH22: =+AF22 -> 10 | AI22: =+AG22 -> 10 | AJ22: =AVERAGE(E22:AI22) -> 10 | AK22: =+AJ22*D22 -> 15
B23: AC S SLIM | C23: 34 | D23: 1 | E23: 34 | F23: =+E23 -> 34 | G23: =+F23 -> 34 | H23: =+G23 -> 34 | I23: =+H23 -> 34 | J23: =+I23 -> 34 | K23: =+J23 -> 34 | L23: =+K23 -> 34 | M23: =+L23 -> 34 | ... AG23: =+AF23 -> 34 | AH23: =+AF23 -> 34 | AI23: =+AG23 -> 34 | AJ23: =AVERAGE(E23:AI23) -> 34 | AK23: =+AJ23*D23 -> 34
B24: MANHATTAN 210 (-) | C24: 5 | D24: 2 | E24: 5 | F24: =+E24 -> 5 | G24: =+F24 -> 5 | H24: =+G24 -> 5 | I24: =+H24 -> 5 | J24: =+I24 -> 5 | K24: =+J24 -> 5 | L24: =+K24 -> 5 | M24: =+L24 -> 5 | ... AG24: =+AF24 -> 5 | AH24: =+AF24 -> 5 | AI24: =+AG24 -> 5 | AJ24: =AVERAGE(E24:AI24) -> 5 | AK24: =+AJ24*D24 -> 10
... B29: Can Cooler | C29: 1 | D29: 1 | E29: 1 | F29: =+E29 -> 1 | G29: =+F29 -> 1 | H29: =+G29 -> 1 | I29: =+H29 -> 1 | J29: =+I29 -> 1 | K29: =+J29 -> 1 | L29: =+K29 -> 1 | M29: =+L29 -> 1 | ... AG29: =+AF29 -> 1 | AH29: =+AF29 -> 1 | AI29: =+AG29 -> 1 | AJ29: =AVERAGE(E29:AI29) -> 1 | AK29: =+AJ29*D29 -> 1
B30: REFACCIONES | C30: 100 | D30: 1 | E30: 100 | F30: =+E30 -> 100 | G30: =+F30 -> 100 | H30: =+G30 -> 100 | I30: =+H30 -> 100 | J30: =+I30 -> 100 | K30: =+J30 -> 100 | L30: =+K30 -> 100 | M30: =+L30 -> 100 | ... O30: =+N30 -> 100 | P30: =+O30+250 -> 350 | Q30: =+P30 -> 350 | R30: =+Q30 -> 350 | S30: =+R30 -> 350 | T30: =+S30 -> 350 | U30: =+T30 -> 350 | V30: =+U30 -> 350 | W30: =+V30 -> 350 | X30: =+W30 -> 350 | ... AG30: =+AF30 -> 350 | AH30: =+AF30 -> 350 | AI30: =+AG30 -> 350 | AJ30: =AVERAGE(E30:AI30) -> 261.29032 | AK30: =+AJ30*D30 -> 261.29032
B31: TOTAL | C31: =SUM(C2:C30) -> 1422 | AJ31: =SUM(AJ2:AJ30) -> 1718.5161 | AK31: =SUM(AK2:AK30) -> 3125.8226
B34: MODELO | C34: N°DE EQUIPOS en facturacion | D34: N°DE EQUIPOS en pestañas | E34: Dif | H34: CÓDIGOS DE COLORES
B35: PARIS 250 (-) | C35: =AI2 -> 47 | D35: ='[1]PARIS 250(-)'!F148 -> 82 | E35: =D35-C35 -> 35 | H35: COLOR | K35: INDICA
B36: PARIS 250 (MEX) | C36: =AI3 -> 40 | D36: ='[1]PARIS 250 (MEX)'!F86 -> 46 | E36: =D36-C36 -> 6 | K36: SALIDA
B37: PARIS 250 (U) | C37: =AI4 -> 1 | D37: ='[1]PARIS 250(U)'!F12 -> 1 | E37: =D37-C37 -> 0 | K37: ENTRADA Y SALIDA
B38: PARIS 210 (-) | C38: =AI5 -> 1104 | D38: =+'[1]PARIS 210 (-) L'!F3704 -> 0 | E38: =D38-C38 -> -1104 | K38: ENTRADA
B39: PARIS 210 (U) | C39: =AI6 -> 27 | D39: ='[1]PARIS 210 (U) LED'!F162 -> 30 | E39: =D39-C39 -> 3
B40: PARIS 210 (MEX) | C40: =AI7 -> 42 | D40: ='[1]PARIS 210 (MEX) LED'!F127 -> 46 | E40: =D40-C40 -> 4
B41: Paris 185 (-) L | C41: =AI8 -> 57 | D41: ='[1]PARIS 185 (-) L '!F194 -> 0 | E41: =D41-C41 -> -57
B42: Paris 185 (MEX) | C42: =AI9 -> 7 | D42: ='[1]PARIS 185 (Mex) L '!F37 -> 3 | E42: =D42-C42 -> -4
B43: Paris 185 (U) L | C43: =AI10 -> 10 | D43: ='[1]PARIS 185 (U) LED'!F115 -> 10 | E43: =D43-C43 -> 0
B44: KYNLEY 210 | C44: =AI11 -> 69 | D44: ='[1]KYNLEY 210 (2)'!F156 -> 0 | E44: =D44-C44 -> -69
B45: KYNLEY 250 | C45: =AI12 -> 123 | D45: ='[1]KYNLEY 250 XL'!F219 -> 1 | E45: =D45-C45 -> -122
B46: MALTA 185 (U) | C46: =AI13 -> 30 | D46: ='[1]MALTA 185 (U) LED'!F76 -> 30 | E46: =D46-C46 -> 0
...

Sheet Desglose Entradas
B2: Contenedor | D2: TGBU7569669 | F2: Contenedor | H2: TRHU6862594 | J2: Contenedor | L2: CAAU5100526 | N2: Contenedor | P2: CAJA 53' | S2: Contenedor | U2: ZCSU6848030 | W2: Contenedor | Y2: JXLU4416017 | AA2: Contenedor | AC2: ZCSU7557467 | AE2: Contenedor | AG2: FSCU8096918 | AI2: Contenedor | AK2: THRU8949266 | AM2: Contenedor | AO2: CMAU7174307 | AQ2: Contenedor | AS2: UETU6476172 | AU2: Contenedor | AW2: SEGU5002509 | AY2: Contenedor | BA2: SEKU5915781 | BC2: Contenedor | BE2: TIIU4920830 | BG2: Contenedor | BI2: CMAU6935891 | BK2: Contenedor | BM2: CMAU6330112 | BO2: Contenedor | BQ2: CMAU6603027
B3: Recepción | C3: SCAHT030058 | D3: 46024 | F3: Recepción | G3: SCAHT030059 | H3: 46024 | J3: Recepción | K3: SCAHT030060 | L3: 46025 | N3: Recepción | O3: SCAHT030066 | P3: 46034 | S3: Recepción | T3: SCAHT030067 | U3: 46035 | W3: Recepción | X3: SCAHT030068 | Y3: 46035 | AA3: Recepción | AB3: SCAHT030069 | AC3: 46036 | AE3: Recepción | AF3: SCAHT030070 | AG3: 46036 | AI3: Recepción | AJ3: SCAHT030073 | AK3: 46045 | AM3: Recepción | AN3: SCAHT030077 | AO3: 46045 | AQ3: Recepción | AR3: SCAHT030074 | AS3: 46045 | AU3: Recepción | AV3: SCAHT030076 | AW3: 46048 | AY3: Recepción | AZ3: SCAHT030079 | BA3: 46048 | BC3: Recepción | BD3: SCAHT030080 | BE3: 46048 | BG3: Recepción | BH3: SCAHT030078 | BI3: 46048 | BK3: Recepción | BL3: SCAHT030075 | BM3: 46048 | BO3: Recepción | BP3: SCAHT030081 | BQ3: 46048
B4: NO. | C4: MODELO | D4: NO SERIE | F4: NO. | G4: MODELO | H4: NO SERIE | J4: NO. | K4: MODELO | L4: NO SERIE | N4: NO. | O4: SKU | P4: DESCRIPCION | Q4: CANTIDAD | S4: NO. | T4: MODELO | U4: NO SERIE | W4: NO. | X4: MODELO | Y4: NO SERIE | AA4: NO. | AB4: MODELO | AC4: NO SERIE | AE4: NO. | AF4: MODELO | AG4: NO SERIE | AI4: NO. | AJ4: MODELO | AK4: NO SERIE | AM4: NO. | AN4: MODELO | AO4: NO SERIE | AQ4: NO. | AR4: MODELO | AS4: NO SERIE | AU4: NO. | AV4: MODELO | AW4: NO SERIE | AY4: NO. | AZ4: MODELO | BA4: NO SERIE | BC4: NO. | BD4: MODELO | BE4: NO SERIE | BG4: NO. | BH4: MODELO | BI4: NO SERIE | BK4: NO. | BL4: MODELO | BM4: NO SERIE | BO4: NO. | BP4: MODELO | BQ4: NO SERIE
B5: 1 | C5: PARIS 210(V) VSAD | D5: 901135 00001590 | F5: 1 | G5: PARIS 210(V) VSAD | H5: 901135 00001540 | J5: 1 | K5: PARIS 185(V) VSAD | L5: 901266 00000015 | N5: 1 | O5: 355847 | P5: Compressor Embraco VNEU213U 220-240V50-60Hz | Q5: 50 | S5: 1 | T5: PARIS 210(V) VSAD | U5: 901135 00001303 | W5: 1 | X5: PARIS EC 185(-)VSAD MEX | Y5: 901266 00000004 | AA5: 1 | AB5: PARIS EC 185(-)VSAD MEX | AC5: 901266 00000010 | AE5: 1 | AF5: PARIS EC 185(-)VSAD MEX | AG5: 901266 00000002 | AI5: 1 | AJ5: PARIS 210 (-) MEX1 | AK5: 47374200000223 | AM5: 1 | AN5: PARIS 210 (-) MEX1 | AO5: 47374200000001 | AQ5: 1 | AR5: PARIS 210 (-) MEX1 | AS5: 47374200000198 | AU5: 1 | AV5: PARIS 210 (-) MEX1 | AW5: 47374200000246 | AY5: 1 | AZ5: PARIS 210 (-) MEX1 | BA5: 47374200000007 | BC5: 1 | BD5: PARIS 210 (-) MEX1 | BE5: 47374200000017 | BG5: 1 | BH5: PARIS 210 (-) MEX1 | BI5: 47374200000008 | BK5: 1 | BL5: PARIS 210 (-) MEX1 | BM5: 47374200000059 | BO5: 1 | BP5: PARIS 210 (-) MEX1 | BQ5: 47374200000028
B6: 2 | C6: PARIS 210(V) VSAD | D6: 901135 00001594 | F6: 2 | G6: PARIS 210(V) VSAD | H6: 901135 00001544 | J6: 2 | K6: PARIS 185(V) VSAD | L6: 901266 00000016 | N6: 2 | O6: 424032 | P6: controller NLV/GP 110-240V 50/60Hz 4668 | Q6: 60 | S6: 2 | T6: PARIS 210(V) VSAD | U6: 901135 00001587 | W6: 2 | X6: PARIS EC 185(-)VSAD MEX | Y6: 901266 00000007 | AA6: 2 | AB6: PARIS EC 185(-)VSAD MEX | AC6: 901266 00000011 | AE6: 2 | AF6: PARIS EC 185(-)VSAD MEX | AG6: 901266 00000003 | AI6: 2 | AJ6: PARIS 210 (-) MEX1 | AK6: 47374200000227 | AM6: 2 | AN6: PARIS 210 (-) MEX1 | AO6: 47374200000002 | AQ6: 2 | AR6: PARIS 210 (-) MEX1 | AS6: 47374200000199 | AU6: 2 | AV6: PARIS 210 (-) MEX1 | AW6: 47374200000253 | AY6: 2 | AZ6: PARIS 210 (-) MEX1 | BA6: 47374200000009 | BC6: 2 | BD6: PARIS 210 (-) MEX1 | BE6: 47374200000018 | BG6: 2 | BH6: PARIS 210 (-) MEX1 | BI6: 47374200000014 | BK6: 2 | BL6: PARIS 210 (-) MEX1 | BM6: 47374200000061 | BO6: 2 | BP6: PARIS 210 (-) MEX1 | BQ6: 47374200000034
B7: 3 | C7: PARIS 210(V) VSAD | D7: 901135 00001597 | F7: 3 | G7: PARIS 210(V) VSAD | H7: 901135 00001585 | J7: 3 | K7: KINLEY XL 250(-) | L7: 901268 00000004 | N7: 3 | O7: 356360 | P7: compressor Secop NLV12.6CN 105H6355 | Q7: 100 | S7: 3 | T7: PARIS 210(V) VSAD | U7: 901135 00001593 | W7: 3 | X7: PARIS EC 185(-)VSAD MEX | Y7: 901266 00000008 | AA7: 3 | AB7: PARIS 210(-)VSAD MEX | AC7: 901267 00000001 | AE7: 3 | AF7: PARIS EC 185(-)VSAD MEX | AG7: 901266 00000005 | AI7: 3 | AJ7: PARIS 210 (-) MEX1 | AK7: 47374200000231 | AM7: 3 | AN7: PARIS 210 (-) MEX1 | AO7: 47374200000003 | AQ7: 3 | AR7: PARIS 210 (-) MEX1 | AS7: 47374200000200 | AU7: 3 | AV7: PARIS 210 (-) MEX1 | AW7: 47374200000254 | AY7: 3 | AZ7: PARIS 210 (-) MEX1 | BA7: 47374200000015 | BC7: 3 | BD7: PARIS 210 (-) MEX1 | BE7: 47374200000077 | BG7: 3 | BH7: PARIS 210 (-) MEX1 | BI7: 47374200000091 | BK7: 3 | BL7: PARIS 210 (-) MEX1 | BM7: 47374200000063 | BO7: 3 | BP7: PARIS 210 (-) MEX1 | BQ7: 47374200000038
B8: 4 | C8: PARIS 210(V) VSAD | D8: 901135 00001607 | F8: 4 | G8: PARIS 210(V) VSAD | H8: 901135 00001586 | J8: 4 | K8: KINLEY XL 250(-) | L8: 901268 00000005 | N8: 4 | O8: 266479 | P8: control panel Secop SLV105N9510 TYP CRA162 | Q8: 40 | S8: 4 | T8: PARIS 210(V) VSAD | U8: 901135 00001598 | W8: 4 | X8: PARIS EC 185(-)VSAD MEX | Y8: 901266 00000009 | AA8: 4 | AB8: PARIS 210(-)VSAD MEX | AC8: 901267 00000002 | AE8: 4 | AF8: PARIS EC 185(-)VSAD MEX | AG8: 901266 00000006 | AI8: 4 | AJ8: PARIS 210 (-) MEX1 | AK8: 47374200000232 | AM8: 4 | AN8: PARIS 210 (-) MEX1 | AO8: 47374200000004 | AQ8: 4 | AR8: PARIS 210 (-) MEX1 | AS8: 47374200000201 | AU8: 4 | AV8: PARIS 210 (-) MEX1 | AW8: 47374200000259 | AY8: 4 | AZ8: PARIS 210 (-) MEX1 | BA8: 47374200000016 | BC8: 4 | BD8: PARIS 210 (-) MEX1 | BE8: 47374200000078 | BG8: 4 | BH8: PARIS 210 (-) MEX1 | BI8: 47374200000092 | BK8: 4 | BL8: PARIS 210 (-) MEX1 | BM8: 47374200000066 | BO8: 4 | BP8: PARIS 210 (-) MEX1 | BQ8: 47374200000041
B9: 5 | C9: PARIS 210(V) VSAD | D9: 901135 00001613 | F9: 5 | G9: PARIS 210(V) VSAD | H9: 901135 00001588 | J9: 5 | K9: KINLEY XL 250(-) | L9: 901268 00000006 | S9: 5 | T9: PARIS 210(V) VSAD | U9: 901135 00001619 | W9: 5 | X9: PARIS EC 185(-)VSAD MEX | Y9: 901266 00000012 | AA9: 5 | AB9: PARIS 210(-)VSAD MEX | AC9: 901267 00000003 | AE9: 5 | AF9: PARIS 250 (-) VSAD MEX | AG9: 901265 00000002 | AI9: 5 | AJ9: PARIS 210 (-) MEX1 | AK9: 47374200000245 | AM9: 5 | AN9: PARIS 210 (-) MEX1 | AO9: 47374200000005 | AQ9: 5 | AR9: PARIS 210 (-) MEX1 | AS9: 47374200000203 | AU9: 5 | AV9: PARIS 210 (-) MEX1 | AW9: 47374200000260 | AY9: 5 | AZ9: PARIS 210 (-) MEX1 | BA9: 47374200000019 | BC9: 5 | BD9: PARIS 210 (-) MEX1 | BE9: 47374200000079 | BG9: 5 | BH9: PARIS 210 (-) MEX1 | BI9: 47374200000100 | BK9: 5 | BL9: PARIS 210 (-) MEX1 | BM9: 47374200000067 | BO9: 5 | BP9: PARIS 210 (-) MEX1 | BQ9: 47374200000122
B10: 6 | C10: PARIS 210(V) VSAD | D10: 901135 00001614 | F10: 6 | G10: PARIS 210(V) VSAD | H10: 901135 00001589 | J10: 6 | K10: KINLEY XL 250(-) | L10: 901268 00000008 | S10: 6 | T10: PARIS 210(V) VSAD | U10: 901135 00001624 | W10: 6 | X10: PARIS EC 185(-)VSAD MEX | Y10: 901266 00000013 | AA10: 6 | AB10: PARIS 210(-)VSAD MEX | AC10: 901267 00000004 | AE10: 6 | AF10: PARIS 250 (-) VSAD MEX | AG10: 901265 00000003 | AI10: 6 | AJ10: PARIS 210 (-) MEX1 | AK10: 47374200000273 | AM10: 6 | AN10: PARIS 210 (-) MEX1 | AO10: 47374200000006 | AQ10: 6 | AR10: PARIS 210 (-) MEX1 | AS10: 47374200000217 | AU10: 6 | AV10: PARIS 210 (-) MEX1 | AW10: 47374200000261 | AY10: 6 | AZ10: PARIS 210 (-) MEX1 | BA10: 47374200000020 | BC10: 6 | BD10: PARIS 210 (-) MEX1 | BE10: 47374200000080 | BG10: 6 | BH10: PARIS 210 (-) MEX1 | BI10: 47374200000107 | BK10: 6 | BL10: PARIS 210 (-) MEX1 | BM10: 47374200000070 | BO10: 6 | BP10: PARIS 210 (-) MEX1 | BQ10: 47374200000123
B11: 7 | C11: PARIS 210(V) VSAD | D11: 901135 00001615 | F11: 7 | G11: PARIS 210(V) VSAD | H11: 901135 00001591 | J11: 7 | K11: KINLEY XL 250(-) | L11: 901268 00000009 | S11: 7 | T11: PARIS 210(V) VSAD | U11: 901135 00001627 | W11: 7 | X11: PARIS EC 185(-)VSAD MEX | Y11: 901266 00000014 | AA11: 7 | AB11: PARIS 210(-)VSAD MEX | AC11: 901267 00000005 | AE11: 7 | AF11: PARIS 250 (-) VSAD MEX | AG11: 901265 00000004 | AI11: 7 | AJ11: PARIS 210 (-) MEX1 | AK11: 47374200000274 | AM11: 7 | AN11: PARIS 210 (-) MEX1 | AO11: 47374200000010 | AQ11: 7 | AR11: PARIS 210 (-) MEX1 | AS11: 47374200000219 | AU11: 7 | AV11: PARIS 210 (-) MEX1 | AW11: 47374200000262 | AY11: 7 | AZ11: PARIS 210 (-) MEX1 | BA11: 47374200000021 | BC11: 7 | BD11: PARIS 210 (-) MEX1 | BE11: 47374200000081 | BG11: 7 | BH11: PARIS 210 (-) MEX1 | BI11: 47374200000108 | BK11: 7 | BL11: PARIS 210 (-) MEX1 | BM11: 47374200000071 | BO11: 7 | BP11: PARIS 210 (-) MEX1 | BQ11: 47374200000124
B12: 8 | C12: PARIS 210(V) VSAD | D12: 901135 00001616 | F12: 8 | G12: PARIS 210(V) VSAD | H12: 901135 00001596 | J12: 8 | K12: KINLEY XL 250(-) | L12: 901268 00000011 | S12: 8 | T12: PARIS 210(V) VSAD | U12: 901135 00001651 | W12: 8 | X12: PARIS EC 185(-)VSAD MEX | Y12: 901266 00000017 | AA12: 8 | AB12: PARIS 210(-)VSAD MEX | AC12: 901267 00000006 | AE12: 8 | AF12: PARIS 250 (-) VSAD MEX | AG12: 901265 00000005 | AI12: 8 | AJ12: PARIS 210 (-) MEX1 | AK12: 47374200000275 | AM12: 8 | AN12: PARIS 210 (-) MEX1 | AO12: 47374200000011 | AQ12: 8 | AR12: PARIS 210 (-) MEX1 | AS12: 47374200000221 | AU12: 8 | AV12: PARIS 210 (-) MEX1 | AW12: 47374200000263 | AY12: 8 | AZ12: PARIS 210 (-) MEX1 | BA12: 47374200000022 | BC12: 8 | BD12: PARIS 210 (-) MEX1 | BE12: 47374200000082 | BG12: 8 | BH12: PARIS 210 (-) MEX1 | BI12: 47374200000109 | BK12: 8 | BL12: PARIS 210 (-) MEX1 | BM12: 47374200000072 | BO12: 8 | BP12: PARIS 210 (-) MEX1 | BQ12: 47374200000128
B13: 9 | C13: PARIS 210(V) VSAD | D13: 901135 00001618 | F13: 9 | G13: PARIS 210(V) VSAD | H13: 901135 00001599 | J13: 9 | K13: KINLEY XL 250(-) | L13: 901268 00000015 | S13: 9 | T13: PARIS 210(V) VSAD | U13: 901135 00001662 | W13: 9 | X13: KINLEY XL 250 KPRN MEX/JBS | Y13: 901268 00000003 | AA13: 9 | AB13: PARIS 210(-)VSAD MEX | AC13: 901267 00000007 | AE13: 9 | AF13: PARIS 250 (-) VSAD MEX | AG13: 901265 00000006 | AI13: 9 | AJ13: PARIS 210 (-) MEX1 | AK13: 47374200000276 | AM13: 9 | AN13: PARIS 210 (-) MEX1 | AO13: 47374200000012 | AQ13: 9 | AR13: PARIS 210 (-) MEX1 | AS13: 47374200000222 | AU13: 9 | AV13: PARIS 210 (-) MEX1 | AW13: 47374200000264 | AY13: 9 | AZ13: PARIS 210 (-) MEX1 | BA13: 47374200000023 | BC13: 9 | BD13: PARIS 210 (-) MEX1 | BE13: 47374200000083 | BG13: 9 | BH13: PARIS 210 (-) MEX1 | BI13: 47374200000110 | BK13: 9 | BL13: PARIS 210 (-) MEX1 | BM13: 47374200000073 | BO13: 9 | BP13: PARIS 210 (-) MEX1 | BQ13: 47374200000129
B14: 10 | C14: PARIS 210(V) VSAD | D14: 901135 00001620 | F14: 10 | G14: PARIS 210(V) VSAD | H14: 901135 00001601 | J14: 10 | K14: KINLEY XL 250(-) | L14: 901268 00000016 | S14: 10 | T14: PARIS 210(V) VSAD | U14: 901135 00001664 | W14: 10 | X14: KINLEY XL 250 KPRN MEX/JBS | Y14: 901268 00000007 | AA14: 10 | AB14: PARIS 210(-)VSAD MEX | AC14: 901267 00000008 | AE14: 10 | AF14: PARIS 250 (-) VSAD MEX | AG14: 901265 00000007 | AI14: 10 | AJ14: PARIS 210 (-) MEX1 | AK14: 47374200000278 | AM14: 10 | AN14: PARIS 210 (-) MEX1 | AO14: 47374200000013 | AQ14: 10 | AR14: PARIS 210 (-) MEX1 | AS14: 47374200000224 | AU14: 10 | AV14: PARIS 210 (-) MEX1 | AW14: 47374200000265 | AY14: 10 | AZ14: PARIS 210 (-) MEX1 | BA14: 47374200000024 | BC14: 10 | BD14: PARIS 210 (-) MEX1 | BE14: 47374200000084 | BG14: 10 | BH14: PARIS 210 (-) MEX1 | BI14: 47374200000111 | BK14: 10 | BL14: PARIS 210 (-) MEX1 | BM14: 47374200000074 | BO14: 10 | BP14: PARIS 210 (-) MEX1 | BQ14: 47374200000130
B15: 11 | C15: PARIS 210(V) VSAD | D15: 901135 00001621 | F15: 11 | G15: PARIS 210(V) VSAD | H15: 901135 00001602 | S15: 11 | T15: PARIS 210(V) VSAD | U15: 901135 00001665 | W15: 11 | X15: KINLEY XL 250 KPRN MEX/JBS | Y15: 901268 00000010 | AA15: 11 | AB15: PARIS 210(-)VSAD MEX | AC15: 901267 00000009 | AE15: 11 | AF15: PARIS 250 (-) VSAD MEX | AG15: 901265 00000008 | AI15: 11 | AJ15: PARIS 210 (-) MEX1 | AK15: 47374200000279 | AM15: 11 | AN15: PARIS 210 (-) MEX1 | AO15: 47374200000039 | AQ15: 11 | AR15: PARIS 210 (-) MEX1 | AS15: 47374200000225 | AU15: 11 | AV15: PARIS 210 (-) MEX1 | AW15: 47374200000266 | AY15: 11 | AZ15: PARIS 210 (-) MEX1 | BA15: 47374200000025 | BC15: 11 | BD15: PARIS 210 (-) MEX1 | BE15: 47374200000085 | BG15: 11 | BH15: PARIS 210 (-) MEX1 | BI15: 47374200000112 | BK15: 11 | BL15: PARIS 210 (-) MEX1 | BM15: 47374200000075 | BO15: 11 | BP15: PARIS 210 (-) MEX1 | BQ15: 47374200000131
B16: 12 | C16: PARIS 210(V) VSAD | D16: 901135 00001622 | F16: 12 | G16: PARIS 210(V) VSAD | H16: 901135 00001603 | S16: 12 | T16: PARIS 210(V) VSAD | U16: 901135 00001667 | W16: 12 | X16: KINLEY XL 250 KPRN MEX/JBS | Y16: 901268 00000012 | AA16: 12 | AB16: PARIS 210(-)VSAD MEX | AC16: 901267 00000010 | AE16: 12 | AF16: PARIS 250 (-) VSAD MEX | AG16: 901265 00000009 | AI16: 12 | AJ16: PARIS 210 (-) MEX1 | AK16: 47374200000280 | AM16: 12 | AN16: PARIS 210 (-) MEX1 | AO16: 47374200000044 | AQ16: 12 | AR16: PARIS 210 (-) MEX1 | AS16: 47374200000226 | AU16: 12 | AV16: PARIS 210 (-) MEX1 | AW16: 47374200000267 | AY16: 12 | AZ16: PARIS 210 (-) MEX1 | BA16: 47374200000026 | BC16: 12 | BD16: PARIS 210 (-) MEX1 | BE16: 47374200000086 | BG16: 12 | BH16: PARIS 210 (-) MEX1 | BI16: 47374200000113 | BK16: 12 | BL16: PARIS 210 (-) MEX1 | BM16: 47374200000076 | BO16: 12 | BP16: PARIS 210 (-) MEX1 | BQ16: 47374200000132
B17: 13 | C17: PARIS 210(V) VSAD | D17: 901135 00001623 | F17: 13 | G17: PARIS 210(V) VSAD | H17: 901135 00001604 | S17: 13 | T17: PARIS 210(V) VSAD | U17: 901135 00001668 | W17: 13 | X17: KINLEY XL 250 KPRN MEX/JBS | Y17: 901268 00000013 | AA17: 13 | AB17: PARIS 210(-)VSAD MEX | AC17: 901267 00000011 | AE17: 13 | AF17: KINLEY XL 210 KPRN MEX | AG17: 901269 00000003 | AI17: 13 | AJ17: PARIS 210 (-) MEX1 | AK17: 47374200000281 | AM17: 13 | AN17: PARIS 210 (-) MEX1 | AO17: 47374200000047 | AQ17: 13 | AR17: PARIS 210 (-) MEX1 | AS17: 47374200000228 | AU17: 13 | AV17: PARIS 210 (-) MEX1 | AW17: 47374200000268 | AY17: 13 | AZ17: PARIS 210 (-) MEX1 | BA17: 47374200000027 | BC17: 13 | BD17: PARIS 210 (-) MEX1 | BE17: 47374200000088 | BG17: 13 | BH17: PARIS 210 (-) MEX1 | BI17: 47374200000149 | BK17: 13 | BL17: PARIS 210 (-) MEX1 | BM17: 47374200000116 | BO17: 13 | BP17: PARIS 210 (-) MEX1 | BQ17: 47374200000133
B18: 14 | C18: PARIS 210(V) VSAD | D18: 901135 00001625 | F18: 14 | G18: PARIS 210(V) VSAD | H18: 901135 00001605 | S18: 14 | T18: PARIS 210(V) VSAD | U18: 901135 00001669 | W18: 14 | X18: KINLEY XL 250 KPRN MEX/JBS | Y18: 901268 00000014 | AA18: 14 | AB18: PARIS 210(-)VSAD MEX | AC18: 901267 00000012 | AE18: 14 | AF18: KINLEY XL 210 KPRN MEX | AG18: 901269 00000004 | AI18: 14 | AJ18: PARIS 210 (-) MEX1 | AK18: 47374200000282 | AM18: 14 | AN18: PARIS 210 (-) MEX1 | AO18: 47374200000048 | AQ18: 14 | AR18: PARIS 210 (-) MEX1 | AS18: 47374200000229 | AU18: 14 | AV18: PARIS 210 (-) MEX1 | AW18: 47374200000269 | AY18: 14 | AZ18: PARIS 210 (-) MEX1 | BA18: 47374200000029 | BC18: 14 | BD18: PARIS 210 (-) MEX1 | BE18: 47374200000090 | BG18: 14 | BH18: PARIS 210 (-) MEX1 | BI18: 47374200000151 | BK18: 14 | BL18: PARIS 210 (-) MEX1 | BM18: 47374200000117 | BO18: 14 | BP18: PARIS 210 (-) MEX1 | BQ18: 47374200000134
B19: 15 | C19: PARIS 210(V) VSAD | D19: 901135 00001626 | F19: 15 | G19: PARIS 210(V) VSAD | H19: 901135 00001606 | S19: 15 | T19: PARIS 210(V) VSAD | U19: 901135 00001670 | AA19: 15 | AB19: PARIS 210(-)VSAD MEX | AC19: 901267 00000013 | AE19: 15 | AF19: KINLEY XL 210 KPRN MEX | AG19: 901269 00000005 | AI19: 15 | AJ19: PARIS 210 (-) MEX1 | AK19: 47374200000283 | AM19: 15 | AN19: PARIS 210 (-) MEX1 | AO19: 47374200000049 | AQ19: 15 | AR19: PARIS 210 (-) MEX1 | AS19: 47374200000230 | AU19: 15 | AV19: PARIS 210 (-) MEX1 | AW19: 47374200000270 | AY19: 15 | AZ19: PARIS 210 (-) MEX1 | BA19: 47374200000030 | BC19: 15 | BD19: PARIS 210 (-) MEX1 | BE19: 47374200000135 | BG19: 15 | BH19: PARIS 210 (-) MEX1 | BI19: 47374200000152 | BK19: 15 | BL19: PARIS 210 (-) MEX1 | BM19: 47374200000118 | BO19: 15 | BP19: PARIS 210 (-) MEX1 | BQ19: 47374200000136
B20: 16 | C20: PARIS 210(V) VSAD | D20: 901135 00001628 | F20: 16 | G20: PARIS 210(V) VSAD | H20: 901135 00001608 | S20: 16 | T20: PARIS 210(V) VSAD | U20: 901135 00001671 | AA20: 16 | AB20: PARIS 210(-)VSAD MEX | AC20: 901267 00000014 | AE20: 16 | AF20: KINLEY XL 210 KPRN MEX | AG20: 901269 00000006 | AI20: 16 | AJ20: PARIS 210 (-) MEX1 | AK20: 47374200000284 | AM20: 16 | AN20: PARIS 210 (-) MEX1 | AO20: 47374200000050 | AQ20: 16 | AR20: PARIS 210 (-) MEX1 | AS20: 47374200000233 | AU20: 16 | AV20: PARIS 210 (-) MEX1 | AW20: 47374200000271 | AY20: 16 | AZ20: PARIS 210 (-) MEX1 | BA20: 47374200000031 | BC20: 16 | BD20: PARIS 210 (-) MEX1 | BE20: 47374200000139 | BG20: 16 | BH20: PARIS 210 (-) MEX1 | BI20: 47374200000156 | BK20: 16 | BL20: PARIS 210 (-) MEX1 | BM20: 47374200000119 | BO20: 16 | BP20: PARIS 210 (-) MEX1 | BQ20: 47374200000137
B21: 17 | C21: PARIS 210(V) VSAD | D21: 901135 00001629 | F21: 17 | G21: PARIS 210(V) VSAD | H21: 901135 00001609 | S21: 17 | T21: PARIS 210(V) VSAD | U21: 901135 00001672 | AA21: 17 | AB21: PARIS 210(-)VSAD MEX | AC21: 901267 00000015 | AE21: 17 | AF21: KINLEY XL 210 KPRN MEX | AG21: 901269 00000007 | AI21: 17 | AJ21: PARIS 210 (-) MEX1 | AK21: 47374200000285 | AM21: 17 | AN21: PARIS 210 (-) MEX1 | AO21: 47374200000051 | AQ21: 17 | AR21: PARIS 210 (-) MEX1 | AS21: 47374200000234 | AU21: 17 | AV21: PARIS 210 (-) MEX1 | AW21: 47374200000272 | AY21: 17 | AZ21: PARIS 210 (-) MEX1 | BA21: 47374200000032 | BC21: 17 | BD21: PARIS 210 (-) MEX1 | BE21: 47374200000140 | BG21: 17 | BH21: PARIS 210 (-) MEX1 | BI21: 47374200000160 | BK21: 17 | BL21: PARIS 210 (-) MEX1 | BM21: 47374200000120 | BO21: 17 | BP21: PARIS 210 (-) MEX1 | BQ21: 47374200000138
B22: 18 | C22: PARIS 210(V) VSAD | D22: 901135 00001633 | F22: 18 | G22: PARIS 210(V) VSAD | H22: 901135 00001610 | S22: 18 | T22: PARIS 210(V) VSAD | U22: 901135 00001673 | AA22: 18 | AB22: PARIS 210(-)VSAD MEX | AC22: 901267 00000016 | AE22: 18 | AF22: KINLEY XL 210 KPRN MEX | AG22: 901269 00000008 | AI22: 18 | AJ22: PARIS 210 (-) MEX1 | AK22: 47374200000286 | AM22: 18 | AN22: PARIS 210 (-) MEX1 | AO22: 47374200000052 | AQ22: 18 | AR22: PARIS 210 (-) MEX1 | AS22: 47374200000235 | AU22: 18 | AV22: PARIS 210 (-) MEX1 | AW22: 47374200000277 | AY22: 18 | AZ22: PARIS 210 (-) MEX1 | BA22: 47374200000033 | BC22: 18 | BD22: PARIS 210 (-) MEX1 | BE22: 47374200000141 | BG22: 18 | BH22: PARIS 210 (-) MEX1 | BI22: 47374200000163 | BK22: 18 | BL22: PARIS 210 (-) MEX1 | BM22: 47374200000121 | BO22: 18 | BP22: PARIS 210 (-) MEX1 | BQ22: 47374200000142
B23: 19 | C23: PARIS 210(V) VSAD | D23: 901135 00001642 | F23: 19 | G23: PARIS 210(V) VSAD | H23: 901135 00001611 | S23: 19 | T23: PARIS 210(V) VSAD | U23: 901135 00001674 | AA23: 19 | AB23: PARIS 210(-)VSAD MEX | AC23: 901267 00000018 | AI23: 19 | AJ23: PARIS 210 (-) MEX1 | AK23: 47374200000287 | AM23: 19 | AN23: PARIS 210 (-) MEX1 | AO23: 47374200000053 | AQ23: 19 | AR23: PARIS 210 (-) MEX1 | AS23: 47374200000236 | AU23: 19 | AV23: PARIS 210 (-) MEX1 | AW23: 47374200000319 | AY23: 19 | AZ23: PARIS 210 (-) MEX1 | BA23: 47374200000035 | BC23: 19 | BD23: PARIS 210 (-) MEX1 | BE23: 47374200000143 | BG23: 19 | BH23: PARIS 210 (-) MEX1 | BI23: 47374200000191 | BK23: 19 | BL23: PARIS 210 (-) MEX1 | BM23: 47374200000125 | BO23: 19 | BP23: PARIS 210 (-) MEX1 | BQ23: 47374200000145
B24: 20 | C24: PARIS 210(V) VSAD | D24: 901135 00001646 | F24: 20 | G24: PARIS 210(V) VSAD | H24: 901135 00001612 | S24: 20 | T24: PARIS 210(V) VSAD | U24: 901135 00001675 | AA24: 20 | AB24: PARIS 210(-)VSAD MEX | AC24: 901267 00000019 | AI24: 20 | AJ24: PARIS 210 (-) MEX1 | AK24: 47374200000288 | AM24: 20 | AN24: PARIS 210 (-) MEX1 | AO24: 47374200000054 | AQ24: 20 | AR24: PARIS 210 (-) MEX1 | AS24: 47374200000237 | AU24: 20 | AV24: PARIS 210 (-) MEX1 | AW24: 47374200000322 | AY24: 20 | AZ24: PARIS 210 (-) MEX1 | BA24: 47374200000036 | BC24: 20 | BD24: PARIS 210 (-) MEX1 | BE24: 47374200000144 | BG24: 20 | BH24: PARIS 210 (-) MEX1 | BI24: 47374200000192 | BK24: 20 | BL24: PARIS 210 (-) MEX1 | BM24: 47374200000126 | BO24: 20 | BP24: PARIS 210 (-) MEX1 | BQ24: 47374200000146
B25: 21 | C25: PARIS 210(V) VSAD | D25: 901135 00001647 | F25: 21 | G25: PARIS 210(V) VSAD | H25: 901135 00001617 | S25: 21 | T25: PARIS 210(V) VSAD | U25: 901135 00001676 | AA25: 21 | AB25: PARIS 210(-)VSAD MEX | AC25: 901267 00000020 | AI25: 21 | AJ25: PARIS 210 (-) MEX1 | AK25: 47374200000289 | AM25: 21 | AN25: PARIS 210 (-) MEX1 | AO25: 47374200000055 | AQ25: 21 | AR25: PARIS 210 (-) MEX1 | AS25: 47374200000240 | AU25: 21 | AV25: PARIS 210 (-) MEX1 | AW25: 47374200000323 | AY25: 21 | AZ25: PARIS 210 (-) MEX1 | BA25: 47374200000037 | BC25: 21 | BD25: PARIS 210 (-) MEX1 | BE25: 47374200000170 | BG25: 21 | BH25: PARIS 210 (-) MEX1 | BI25: 47374200000193 | BK25: 21 | BL25: PARIS 210 (-) MEX1 | BM25: 47374200000127 | BO25: 21 | BP25: PARIS 210 (-) MEX1 | BQ25: 47374200000147
B26: 22 | C26: PARIS 210(V) VSAD | D26: 901135 00001648 | F26: 22 | G26: PARIS 210(V) VSAD | H26: 901135 00001630 | S26: 22 | T26: PARIS 210(V) VSAD | U26: 901135 00001677 | AA26: 22 | AB26: PARIS 210(-)VSAD MEX | AC26: 901267 00000021 | AI26: 22 | AJ26: PARIS 210 (-) MEX1 | AK26: 47374200000291 | AM26: 22 | AN26: PARIS 210 (-) MEX1 | AO26: 47374200000056 | AQ26: 22 | AR26: PARIS 210 (-) MEX1 | AS26: 47374200000241 | AU26: 22 | AV26: PARIS 210 (-) MEX1 | AW26: 47374200000324 | AY26: 22 | AZ26: PARIS 210 (-) MEX1 | BA26: 47374200000040 | BC26: 22 | BD26: PARIS 210 (-) MEX1 | BE26: 47374200000171 | BG26: 22 | BH26: PARIS 210 (-) MEX1 | BI26: 47374200000194 | BK26: 22 | BL26: PARIS 210 (-) MEX1 | BM26: 47374200000172 | BO26: 22 | BP26: PARIS 210 (-) MEX1 | BQ26: 47374200000148
B27: 23 | C27: PARIS 210(V) VSAD | D27: 901135 00001649 | F27: 23 | G27: PARIS 210(V) VSAD | H27: 901135 00001631 | S27: 23 | T27: PARIS 210(V) VSAD | U27: 901135 00001678 | AA27: 23 | AB27: PARIS 210(-)VSAD MEX | AC27: 901267 00000022 | AI27: 23 | AJ27: PARIS 210 (-) MEX1 | AK27: 47374200000292 | AM27: 23 | AN27: PARIS 210 (-) MEX1 | AO27: 47374200000057 | AQ27: 23 | AR27: PARIS 210 (-) MEX1 | AS27: 47374200000242 | AU27: 23 | AV27: PARIS 210 (-) MEX1 | AW27: 47374200000325 | AY27: 23 | AZ27: PARIS 210 (-) MEX1 | BA27: 47374200000042 | BC27: 23 | BD27: PARIS 210 (-) MEX1 | BE27: 47374200000173 | BG27: 23 | BH27: PARIS 210 (-) MEX1 | BI27: 47374200000195 | BK27: 23 | BL27: PARIS 210 (-) MEX1 | BM27: 47374200000220 | BO27: 23 | BP27: PARIS 210 (-) MEX1 | BQ27: 47374200000150
B28: 24 | C28: PARIS 210(V) VSAD | D28: 901135 00001650 | F28: 24 | G28: PARIS 210(V) VSAD | H28: 901135 00001632 | S28: 24 | T28: PARIS 210(V) VSAD | U28: 901135 00001679 | AA28: 24 | AB28: PARIS 210(-)VSAD MEX | AC28: 901267 00000023 | AI28: 24 | AJ28: PARIS 210 (-) MEX1 | AK28: 47374200000293 | AM28: 24 | AN28: PARIS 210 (-) MEX1 | AO28: 47374200000058 | AQ28: 24 | AR28: PARIS 210 (-) MEX1 | AS28: 47374200000243 | AU28: 24 | AV28: PARIS 210 (-) MEX1 | AW28: 47374200000326 | AY28: 24 | AZ28: PARIS 210 (-) MEX1 | BA28: 47374200000043 | BC28: 24 | BD28: PARIS 210 (-) MEX1 | BE28: 47374200000174 | BG28: 24 | BH28: PARIS 210 (-) MEX1 | BI28: 47374200000197 | BK28: 24 | BL28: PARIS 210 (-) MEX1 | BM28: 47374200000238 | BO28: 24 | BP28: PARIS 210 (-) MEX1 | BQ28: 47374200000153
B29: 25 | C29: PARIS 210(V) VSAD | D29: 901135 00001652 | F29: 25 | G29: PARIS 210(V) VSAD | H29: 901135 00001634 | S29: 25 | T29: PARIS 210(V) VSAD | U29: 901135 00001680 | AA29: 25 | AB29: PARIS 210(-)VSAD MEX | AC29: 901267 00000024 | AI29: 25 | AJ29: PARIS 210 (-) MEX1 | AK29: 47374200000294 | AM29: 25 | AN29: PARIS 210 (-) MEX1 | AO29: 47374200000060 | AQ29: 25 | AR29: PARIS 210 (-) MEX1 | AS29: 47374200000290 | AU29: 25 | AV29: PARIS 210 (-) MEX1 | AW29: 47374200000327 | AY29: 25 | AZ29: PARIS 210 (-) MEX1 | BA29: 47374200000045 | BC29: 25 | BD29: PARIS 210 (-) MEX1 | BE29: 47374200000175 | BG29: 25 | BH29: PARIS 210 (-) MEX1 | BI29: 47374200000202 | BK29: 25 | BL29: PARIS 210 (-) MEX1 | BM29: 47374200000239 | BO29: 25 | BP29: PARIS 210 (-) MEX1 | BQ29: 47374200000154
B30: 26 | C30: PARIS 210(V) VSAD | D30: 901135 00001653 | F30: 26 | G30: PARIS 210(V) VSAD | H30: 901135 00001635 | S30: 26 | T30: PARIS 210(V) VSAD | U30: 901135 00001681 | AA30: 26 | AB30: PARIS 210(-)VSAD MEX | AC30: 901267 00000025 | AI30: 26 | AJ30: PARIS 210 (-) MEX1 | AK30: 47374200000295 | AM30: 26 | AN30: PARIS 210 (-) MEX1 | AO30: 47374200000062 | AQ30: 26 | AR30: PARIS 210 (-) MEX1 | AS30: 47374200000297 | AU30: 26 | AV30: PARIS 210 (-) MEX1 | AW30: 47374200000328 | AY30: 26 | AZ30: PARIS 210 (-) MEX1 | BA30: 47374200000046 | BC30: 26 | BD30: PARIS 210 (-) MEX1 | BE30: 47374200000178 | BG30: 26 | BH30: PARIS 210 (-) MEX1 | BI30: 47374200000204 | BK30: 26 | BL30: PARIS 210 (-) MEX1 | BM30: 47374200000244 | BO30: 26 | BP30: PARIS 210 (-) MEX1 | BQ30: 47374200000155
B31: 27 | C31: PARIS 210(V) VSAD | D31: 901135 00001654 | F31: 27 | G31: PARIS 210(V) VSAD | H31: 901135 00001636 | S31: 27 | T31: PARIS 210(V) VSAD | U31: 901135 00001682 | AA31: 27 | AB31: PARIS 210(-)VSAD MEX | AC31: 901267 00000026 | AI31: 27 | AJ31: PARIS 210 (-) MEX1 | AK31: 47374200000296 | AM31: 27 | AN31: PARIS 210 (-) MEX1 | AO31: 47374200000064 | AQ31: 27 | AR31: PARIS 210 (-) MEX1 | AS31: 47374200000298 | AU31: 27 | AV31: PARIS 210 (-) MEX1 | AW31: 47374200000329 | AY31: 27 | AZ31: PARIS 210 (-) MEX1 | BA31: 47374200000087 | BC31: 27 | BD31: PARIS 210 (-) MEX1 | BE31: 47374200000179 | BG31: 27 | BH31: PARIS 210 (-) MEX1 | BI31: 47374200000205 | BK31: 27 | BL31: PARIS 210 (-) MEX1 | BM31: 47374200000247 | BO31: 27 | BP31: PARIS 210 (-) MEX1 | BQ31: 47374200000157
B32: 28 | C32: PARIS 210(V) VSAD | D32: 901135 00001655 | F32: 28 | G32: PARIS 210(V) VSAD | H32: 901135 00001637 | S32: 28 | T32: PARIS 210(V) VSAD | U32: 901135 00001684 | AA32: 28 | AB32: PARIS 210(-)VSAD MEX | AC32: 901267 00000027 | AI32: 28 | AJ32: PARIS 210 (-) MEX1 | AK32: 47374200000300 | AM32: 28 | AN32: PARIS 210 (-) MEX1 | AO32: 47374200000065 | AQ32: 28 | AR32: PARIS 210 (-) MEX1 | AS32: 47374200000299 | AU32: 28 | AV32: PARIS 210 (-) MEX1 | AW32: 47374200000330 | AY32: 28 | AZ32: PARIS 210 (-) MEX1 | BA32: 47374200000089 | BC32: 28 | BD32: PARIS 210 (-) MEX1 | BE32: 47374200000180 | BG32: 28 | BH32: PARIS 210 (-) MEX1 | BI32: 47374200000206 | BK32: 28 | BL32: PARIS 210 (-) MEX1 | BM32: 47374200000248 | BO32: 28 | BP32: PARIS 210 (-) MEX1 | BQ32: 47374200000158
B33: 29 | C33: PARIS 210(V) VSAD | D33: 901135 00001656 | F33: 29 | G33: PARIS 210(V) VSAD | H33: 901135 00001638 | S33: 29 | T33: PARIS 210(V) VSAD | U33: 901135 00001687 | AA33: 29 | AB33: PARIS 210(-)VSAD MEX | AC33: 901267 00000028 | AI33: 29 | AJ33: PARIS 210 (-) MEX1 | AK33: 47374200000301 | AM33: 29 | AN33: PARIS 210 (-) MEX1 | AO33: 47374200000068 | AQ33: 29 | AR33: PARIS 210 (-) MEX1 | AS33: 47374200000302 | AU33: 29 | AV33: PARIS 210 (-) MEX1 | AW33: 47374200000331 | AY33: 29 | AZ33: PARIS 210 (-) MEX1 | BA33: 47374200000093 | BC33: 29 | BD33: PARIS 210 (-) MEX1 | BE33: 47374200000181 | BG33: 29 | BH33: PARIS 210 (-) MEX1 | BI33: 47374200000207 | BK33: 29 | BL33: PARIS 210 (-) MEX1 | BM33: 47374200000249 | BO33: 29 | BP33: PARIS 210 (-) MEX1 | BQ33: 47374200000159
B34: 30 | C34: PARIS 210(V) VSAD | D34: 901135 00001657 | F34: 30 | G34: PARIS 210(V) VSAD | H34: 901135 00001639 | S34: 30 | T34: PARIS 210(V) VSAD | U34: 901135 00001688 | AA34: 30 | AB34: PARIS 210(-)VSAD MEX | AC34: 901267 00000029 | AI34: 30 | AJ34: PARIS 210 (-) MEX1 | AK34: 47374200000308 | AM34: 30 | AN34: PARIS 210 (-) MEX1 | AO34: 47374200000069 | AQ34: 30 | AR34: PARIS 210 (-) MEX1 | AS34: 47374200000303 | AU34: 30 | AV34: PARIS 210 (-) MEX1 | AW34: 47374200000332 | AY34: 30 | AZ34: PARIS 210 (-) MEX1 | BA34: 47374200000094 | BC34: 30 | BD34: PARIS 210 (-) MEX1 | BE34: 47374200000182 | BG34: 30 | BH34: PARIS 210 (-) MEX1 | BI34: 47374200000208 | BK34: 30 | BL34: PARIS 210 (-) MEX1 | BM34: 47374200000250 | BO34: 30 | BP34: PARIS 210 (-) MEX1 | BQ34: 47374200000161
... B38: 34 | C38: PARIS 210(V) VSAD | D38: 901135 00001661 | F38: 34 | G38: PARIS 210(V) VSAD | H38: 901135 00001644 | S38: 34 | T38: PARIS 210(V) VSAD | U38: 901135 00001723 | AA38: 34 | AB38: PARIS 210(-)VSAD MEX | AC38: 901267 00000033 | AI38: 34 | AJ38: PARIS 210 (-) MEX1 | AK38: 47374200000318 | AM38: 34 | AN38: PARIS 210 (-) MEX1 | AO38: 47374200000106 | AQ38: 34 | AR38: PARIS 210 (-) MEX1 | AS38: 47374200000307 | AU38: 34 | AV38: PARIS 210 (-) MEX1 | AW38: 47374200000336 | AY38: 34 | AZ38: PARIS 210 (-) MEX1 | BA38: 47374200000098 | BC38: 34 | BD38: PARIS 210 (-) MEX1 | BE38: 47374200000186 | BG38: 34 | BH38: PARIS 210 (-) MEX1 | BI38: 47374200000212 | BK38: 34 | BL38: PARIS 210 (-) MEX1 | BM38: 47374200000256 | BO38: 34 | BP38: PARIS 210 (-) MEX1 | BQ38: 47374200000166
B39: 35 | C39: PARIS 210(V) VSAD | D39: 901135 00001663 | F39: 35 | G39: PARIS 210(V) VSAD | H39: 901135 00001645 | S39: 35 | T39: PARIS 210(V) VSAD | U39: 901135 00001724 | AI39: 35 | AJ39: PARIS 210 (-) MEX1 | AK39: 47374200000320 | AM39: 35 | AN39: PARIS 210 (-) MEX1 | AO39: 47374200000114 | AQ39: 35 | AR39: PARIS 210 (-) MEX1 | AS39: 47374200000310 | AU39: 35 | AV39: PARIS 210 (-) MEX1 | AW39: 47374200000337 | AY39: 35 | AZ39: PARIS 210 (-) MEX1 | BA39: 47374200000099 | BC39: 35 | BD39: PARIS 210 (-) MEX1 | BE39: 47374200000187 | BG39: 35 | BH39: PARIS 210 (-) MEX1 | BI39: 47374200000213 | BK39: 35 | BL39: PARIS 210 (-) MEX1 | BM39: 47374200000257 | BO39: 35 | BP39: PARIS 210 (-) MEX1 | BQ39: 47374200000167
AI40: 36 | AJ40: PARIS 210 (-) MEX1 | AK40: 47374200000321 | AM40: 36 | AN40: PARIS 210 (-) MEX1 | AO40: 47374200000115 | AQ40: 36 | AR40: PARIS 210 (-) MEX1 | AS40: 47374200000311 | AU40: 36 | AV40: PARIS 210 (-) MEX1 | AW40: 47374200000338 | AY40: 36 | AZ40: PARIS 210 (-) MEX1 | BA40: 47374200000103 | BC40: 36 | BD40: PARIS 210 (-) MEX1 | BE40: 47374200000188 | BG40: 36 | BH40: PARIS 210 (-) MEX1 | BI40: 47374200000214 | BK40: 36 | BL40: PARIS 210 (-) MEX1 | BM40: 47374200000258 | BO40: 36 | BP40: PARIS 210 (-) MEX1 | BQ40: 47374200000168
AI41: 37 | AJ41: PARIS 210 (-) MEX1 | AK41: 47374200000340 | AM41: 37 | AN41: PARIS 210 (-) MEX1 | AO41: 47374200000196 | AQ41: 37 | AR41: PARIS 210 (-) MEX1 | AS41: 47374200000312 | AU41: 37 | AV41: PARIS 210 (-) MEX1 | AW41: 47374200000339 | AY41: 37 | AZ41: PARIS 210 (-) MEX1 | BA41: 47374200000104 | BC41: 37 | BD41: PARIS 210 (-) MEX1 | BE41: 47374200000189 | BG41: 37 | BH41: PARIS 210 (-) MEX1 | BI41: 47374200000215 | BK41: 37 | BL41: PARIS 210 (-) MEX1 | BM41: 47374200000316 | BO41: 37 | BP41: PARIS 210 (-) MEX1 | BQ41: 47374200000169
AI42: 38 | AJ42: PARIS 210 (-) MEX1 | AK42: 47374200000341 | AM42: 38 | AN42: PARIS 210 (-) MEX1 | AO42: 47374200000218 | AQ42: 38 | AR42: PARIS 210 (-) MEX1 | AS42: 47374200000313 | AU42: 38 | AV42: PARIS 210 (-) MEX1 | AW42: 47374200000342 | AY42: 38 | AZ42: PARIS 210 (-) MEX1 | BA42: 47374200000176 | BC42: 38 | BD42: PARIS 210 (-) MEX1 | BE42: 47374200000190 | BG42: 38 | BH42: PARIS 210 (-) MEX1 | BI42: 47374200000216 | BK42: 38 | BL42: PARIS 210 (-) MEX1 | BM42: 47374200000317 | BO42: 38 | BP42: PARIS 210 (-) MEX1 | BQ42: 47374200000177

Sheet Desglose Salidas
B2: RUTA | D2: CASIQUE - 3671 GTO Salam Arboledas | F2: RUTA | H2: SOLICITUD DE SERVICIO AHT 1638 AGUA FRIA | J2: RUTA | L2: CASIQUE - VALLEJO - 2120 - 1842 - SC5 - 786 | N2: RUTA | P2: CASIQUE - YAUTEPEC - 1591 - 1628 - 2090 - 2211 - 2719 - 2859 | R2: RUTA | T2: CASIQUE - ZACATLAN 2 | V2: RUTA | X2: CASIQUE - ACAPULCO- 4031 - 4158 - 4325 - 4087 | Z2: RUTA | AB2: Nueva tienda WildFork CONSTITUYENTES QUERETARO | AD2: RUTA | AF2: Nueva tienda WildFork CONSTITUYENTES QUERETARO | AH2: RUTA | AJ2: CASIQUE - ACAPULCO 3593 - 2639 | AL2: RUTA | AN2: CASIQUE - VALLEJO - TULANCINGO | AP2: RUTA | AR2: CASIQUE - YAUTEPEC 1106-2611-3001 | AT2: RUTA | AV2: CASIQUE - VALLEJO - TULANCINGO | AX2: RUTA | AZ2: CASIQUE - PUEBLA | BB2: RUTA | BD2: CASIQUE - ACAPULCO | BF2: RUTA | BH2: CASIQUE - GUANAJUATO | BJ2: RUTA | BL2: CASIQUE - MET - PUEBLA - LOS REYES | BN2: RUTA | BP2: CASIQUE - PUEBLA XICOTEPEC | BR2: RUTA | BT2: CASIQUE - MORELIA
B3: Recepción | C3: SCCASI080281 | D3: 46024 | F3: Recepción | G3: SCAHT030063 | H3: 46030 | J3: Recepción | K3: SCCASI080284 | L3: 46034 | N3: Recepción | O3: SCCASI080285 | P3: 46034 | R3: Recepción | S3: SCCASI080286 | T3: 46034 | V3: Recepción | W3: SCCASI080287 | X3: 46036 | Z3: Recepción | AA3: SCAHT030064 | AB3: 46037 | AD3: Recepción | AE3: SCAHT030065 | AF3: 46038 | AH3: Recepción | AI3: SCCASI080288 | AJ3: 46038 | AL3: Recepción | AM3: SCCASI080289 | AN3: 46038 | AP3: Recepción | AQ3: SCCASI080290 | AR3: 46043 | AT3: Recepción | AU3: SCCASI080291 | AV3: 46043 | AX3: Recepción | AY3: SCCASI080293 | AZ3: 46045 | BB3: Recepción | BC3: SCCASI080294 | BD3: 46045 | BF3: Recepción | BG3: SCCASI080295 | BH3: 46048 | BJ3: Recepción | BK3: SCCASI080297 | BL3: 46049 | BN3: Recepción | BO3: SCCASI080298 | BP3: 46049 | BR3: Recepción | BS3: SCCASI080299 | BT3: 46050
B4: NO. | C4: MODELO | D4: NO SERIE | F4: NO. | G4: MODELO | H4: NO SERIE | J4: NO. | K4: MODELO | L4: NO SERIE | N4: NO. | O4: MODELO | P4: NO SERIE | R4: NO. | S4: MODELO | T4: NO SERIE | V4: NO. | W4: MODELO | X4: NO SERIE | Z4: NO. | AA4: MODELO | AB4: NO SERIE | AD4: NO. | AE4: MODELO | AF4: NO SERIE | AH4: NO. | AI4: MODELO | AJ4: NO SERIE | AL4: NO. | AM4: MODELO | AN4: NO SERIE | AP4: NO. | AQ4: MODELO | AR4: NO SERIE | AT4: NO. | AU4: MODELO | AV4: NO SERIE | AX4: NO. | AY4: MODELO | AZ4: NO SERIE | BB4: NO. | BC4: MODELO | BD4: NO SERIE | BF4: NO. | BG4: MODELO | BH4: NO SERIE | BJ4: NO. | BK4: MODELO | BL4: NO SERIE | BN4: NO. | BO4: MODELO | BP4: NO SERIE | BR4: NO. | BS4: MODELO | BT4: NO SERIE
B5: 1 | C5: PARIS 210 (-) MEX | D5: 434490 00008346 | F5: 1 | G5: PARIS 210 (-) MEX | H5: 434490 00008310 | J5: 1 | K5: PARIS 210 (-) MEX | L5: 434490 00008306 | N5: 1 | O5: PARIS 210 (-) MEX | P5: 434490 00008309 | R5: 1 | S5: PARIS 210 (-) MEX | T5: 434490 00008338 | V5: 1 | W5: PARIS 210 (-) MEX | X5: 434490 00008534 | Z5: 1 | AA5: KINLEY XL 250 MEX | AB5: 41880800000021 | AD5: 1 | AE5: PARIS 210 (-) VSAD | AF5: 901267 00000031 | AH5: 1 | AI5: PARIS 210 (-) MEX | AJ5: 434490 00008626 | AL5: 1 | AM5: PARIS 210 (-) MEX | AN5: 434490 00008545 | AP5: 1 | AQ5: PARIS 210 (-) MEX | AR5: 434490 00008336 | AT5: 1 | AU5: PARIS 210 (-) MEX | AV5: 434490 00008298 | AX5: 1 | AY5: PARIS 210 (-) MEX | AZ5: 434490 00007794 | BB5: 1 | BC5: PARIS 210 (-) MEX | BD5: 434490 00008516 | BF5: 1 | BG5: PARIS 210 (-) MEX | BH5: 434490 00008653 | BJ5: 1 | BK5: PARIS 210(V) VSAD | BL5: 901135 00001304 | BN5: 1 | BO5: PARIS 210(V) VSAD | BP5: 901135 00001322 | BR5: 1 | BS5: PARIS 210(V) VSAD | BT5: 901135 00001336
B6: 2 | C6: PARIS 210 (-) MEX | D6: 434490 00008327 | J6: 2 | K6: PARIS 210 (-) MEX | L6: 434490 00008326 | N6: 2 | O6: PARIS 210 (-) MEX | P6: 434490 00008366 | V6: 2 | W6: PARIS 210 (-) MEX | X6: 434490 00008597 | Z6: 2 | AA6: KINLEY XL 250 MEX | AB6: 41880800000042 | AD6: 2 | AE6: PARIS 210 (-) VSAD | AF6: 901267 00000015 | AH6: 2 | AI6: PARIS 210 (-) MEX | AJ6: 434490 00008368 | AL6: 2 | AM6: PARIS 210 (-) MEX | AN6: 434490 00008126 | AP6: 2 | AQ6: PARIS 210 (-) MEX | AR6: 434490 00008348 | AT6: 2 | AU6: PARIS 210 (-) MEX | AV6: 434490 00008308 | AX6: 2 | AY6: PARIS 210 (-) MEX | AZ6: 434490 00007791 | BB6: 2 | BC6: PARIS 210 (-) MEX | BD6: 434490 00008552 | BF6: 2 | BG6: PARIS 210 (-) MEX | BH6: 434490 00007498 | BJ6: 2 | BK6: PARIS 210(V) VSAD | BL6: 901135 00001329 | BN6: 2 | BO6: PARIS 210 (-) MEX | BP6: 434490 00007875 | BR6: 2 | BS6: PARIS 210(V) VSAD | BT6: 901135 00001370
B7: 3 | C7: PARIS 210 (-) MEX | D7: 434490 00008325 | J7: 3 | K7: PARIS 210 (-) MEX | L7: 434490 00008311 | N7: 3 | O7: PARIS 210 (-) MEX | P7: 434490 00008351 | V7: 3 | W7: PARIS 210 (-) MEX | X7: 434490 00008504 | Z7: 3 | AA7: KINLEY XL 250 MEX | AB7: 41880800000063 | AD7: 3 | AE7: PARIS 210 (-) VSAD | AF7: 901267 00000026 | AH7: 3 | AI7: PARIS 210 (-) MEX | AJ7: 434490 00008306 | AL7: 3 | AM7: PARIS 210 (-) MEX | AN7: 434490 00008190 | AP7: 3 | AQ7: PARIS 210 (-) MEX | AR7: 434490 00008299 | AT7: 3 | AU7: PARIS 210 (-) MEX | AV7: 434490 00008302 | AX7: 3 | AY7: PARIS 210 (-) MEX | AZ7: 434490 00008596 | BB7: 3 | BC7: PARIS 210 (-) MEX | BD7: 434490 00008185 | BF7: 3 | BG7: PARIS 210 (-) MEX | BH7: 434490 00007543 | BJ7: 3 | BK7: PARIS 210(V) VSAD | BL7: 901135 00001328 | BR7: 3 | BS7: PARIS 210(V) VSAD | BT7: 901135 00001366
B8: 4 | C8: PARIS 210 (-) MEX | D8: 434490 00008304 | J8: 4 | K8: PARIS 210 (-) MEX | L8: 434490 00008337 | N8: 4 | O8: PARIS 210 (-) MEX | P8: 434490 00008341 | V8: 4 | W8: PARIS 210 (-) MEX | X8: 434490 00008670 | Z8: 4 | AA8: KINLEY XL 250 MEX | AB8: 41880800000096 | AD8: 4 | AE8: PARIS 210 (-) VSAD | AF8: 901267 00000012 | AL8: 4 | AM8: PARIS 210 (-) MEX | AN8: 434490 00008359 | AT8: 4 | AU8: PARIS 210 (-) MEX | AV8: 434490 00008519 | AX8: 4 | AY8: PARIS 210 (-) MEX | AZ8: 434490 00008517 | BB8: 4 | BC8: PARIS 210 (-) MEX | BD8: 434490 00008547 | BJ8: 4 | BK8: PARIS 210(V) VSAD | BL8: 901135 00001330 | BR8: 4 | BS8: PARIS 210(V) VSAD | BT8: 901135 00001356
J9: 5 | K9: PARIS 210 (-) MEX | L9: 434490 00008368 | N9: 5 | O9: PARIS 210 (-) MEX | P9: 434490 00008343 | V9: 5 | W9: PARIS 210 (-) MEX | X9: 434490 00008494 | Z9: 5 | AA9: KINLEY XL 250 MEX | AB9: 41880800000099 | AD9: 5 | AE9: PARIS 210 (-) VSAD | AF9: 901267 00000032 | AL9: 5 | AM9: PARIS 210 (-) MEX | AN9: 434490 00008551 | AT9: 5 | AU9: PARIS 210 (-) MEX | AV9: 434490 00008135 | AX9: 5 | AY9: PARIS 210 (-) MEX | AZ9: 434490 00008184 | BB9: 5 | BC9: PARIS 210 (-) MEX | BD9: 434490 00008513 | BJ9: 5 | BK9: PARIS 210(V) VSAD | BL9: 901135 00001321 | BR9: 5 | BS9: PARIS 210(V) VSAD | BT9: 901135 00001350
J10: 6 | K10: PARIS 210 (-) MEX | L10: 434490 00008338 | N10: 6 | O10: PARIS 210 (-) MEX | P10: 434490 00008191 | V10: 6 | W10: PARIS 210 (-) MEX | X10: 434490 00008668 | Z10: 6 | AA10: KINLEY XL 250 MEX | AB10: 41880800000116 | AD10: 6 | AE10: PARIS 210 (-) VSAD | AF10: 901267 00000009 | AL10: 6 | AM10: PARIS 210 (-) MEX | AN10: 434490 00008289 | AT10: 6 | AU10: PARIS 210 (-) MEX | AV10: 434490 00008599 | AX10: 6 | AY10: PARIS 210 (-) MEX | AZ10: 434490 00008142 | BB10: 6 | BC10: PARIS 210 (-) MEX | BD10: 434490 00008335 | BJ10: 6 | BK10: PARIS 210(V) VSAD | BL10: 901135 00001337 | BR10: 6 | BS10: PARIS 210(V) VSAD | BT10: 901135 00001380
V11: 7 | W11: PARIS 210 (-) MEX | X11: 434490 00008613 | Z11: 7 | AA11: KINLEY 210 (-) MEX | AB11: 44639900000076 | AD11: 7 | AE11: PARIS 210 (-) VSAD | AF11: 901267 00000029 | AL11: 7 | AM11: PARIS 210 (-) MEX | AN11: 434490 00008648 | AT11: 7 | AU11: PARIS 210 (-) MEX | AV11: 434490 00008548 | AX11: 7 | AY11: PARIS 210 (-) MEX | AZ11: 434490 00008518 | BR11: 7 | BS11: PARIS 210(V) VSAD | BT11: 901135 00001369
V12: 8 | W12: PARIS 210 (-) MEX | X12: 434490 00008509 | Z12: 8 | AA12: KINLEY 210 (-) MEX | AB12: 44639900000109 | AD12: 8 | AE12: PARIS 210 (-) VSAD | AF12: 901267 00000028 | AL12: 8 | AM12: PARIS 210 (-) MEX | AN12: 434490 00008514 | AT12: 8 | AU12: PARIS 210 (-) MEX | AV12: 434490 00008661 | AX12: 8 | AY12: PARIS 210 (-) MEX | AZ12: 434490 00008549 | BR12: 8 | BS12: PARIS 210(V) VSAD | BT12: 901135 00001384
AD13: 9 | AE13: PARIS 210 (-) VSAD | AF13: 901267 00000013 | AT13: 9 | AU13: PARIS 210 (-) MEX | AV13: 434490 00008295 | AX13: 9 | AY13: PARIS 210 (-) MEX | AZ13: 434490 00008164 | BR13: 9 | BS13: PARIS 210(V) VSAD | BT13: 901135 00001373
AD14: 10 | AE14: PARIS 210 (-) VSAD | AF14: 901267 00000007 | AT14: 10 | AU14: PARIS 210 (-) MEX | AV14: 434490 00007792 | BR14: 10 | BS14: PARIS 210(V) VSAD | BT14: 901135 00001378
AD15: 11 | AE15: PARIS 210 (-) VSAD | AF15: 901267 00000008 | BR15: 11 | BS15: PARIS 210(V) VSAD | BT15: 901135 00001385
AD16: 12 | AE16: PARIS 210 (-) VSAD | AF16: 901267 00000010 | BR16: 12 | BS16: PARIS 210(V) VSAD | BT16: 901135 00001364
AD17: 13 | AE17: PARIS 210 (-) VSAD | AF17: 901267 00000003 | BR17: 13 | BS17: PARIS 210(V) VSAD | BT17: 901135 00001357
AD18: 14 | AE18: PARIS 210 (-) VSAD | AF18: 901267 00000030 | BR18: 14 | BS18: PARIS 210(V) VSAD | BT18: 901135 00001352
AD19: 15 | AE19: PARIS 210 (-) VSAD | AF19: 901267 00000025 | BR19: 15 | BS19: PARIS 210(V) VSAD | BT19: 901135 00001344
AD20: 16 | AE20: PARIS 185 (-) VSAD | AF20: 90126600000002 | BR20: 16 | BS20: PARIS 210(V) VSAD | BT20: 901135 00001339
AD21: 17 | AE21: PARIS 185 (-) VSAD | AF21: 90126600000003 | BR21: 17 | BS21: PARIS 210(V) VSAD | BT21: 901135 00001355
AD22: 18 | AE22: PARIS 185 (-) VSAD | AF22: 90126600000005 | BR22: 18 | BS22: PARIS 210(V) VSAD | BT22: 901135 00001365
AD23: 19 | AE23: PARIS 185 (-) VSAD | AF23: 90126600000006 | BR23: 19 | BS23: PARIS 210(V) VSAD | BT23: 901135 00001359
AD24: 20 | AE24: PARIS 185 (-) VSAD | AF24: 90126600000016 | BR24: 20 | BS24: PARIS 210(V) VSAD | BT24: 901135 00001311
AD25: 21 | AE25: PARIS 250 (-) VSAD | AF25: 90126500000002 | BR25: 21 | BS25: PARIS 210(V) VSAD | BT25: 901135 00001327
AD26: 22 | AE26: PARIS 250 (-) VSAD | AF26: 90126500000003 | BR26: 22 | BS26: PARIS 210(V) VSAD | BT26: 901135 00001360
AD27: 23 | AE27: PARIS 250 (-) VSAD | AF27: 90126500000004 | BR27: 23 | BS27: PARIS 210(V) VSAD | BT27: 901135 00001372
AD28: 24 | AE28: PARIS 250 (-) VSAD | AF28: 90126500000005 | BR28: 24 | BS28: PARIS 210(V) VSAD | BT28: 901135 00001358
AD29: 25 | AE29: PARIS 250 (-) VSAD | AF29: 90126500000006
AD30: 26 | AE30: PARIS 250 (-) VSAD | AF30: 90126500000008
AD31: 27 | AE31: KINLEY 210 (-) MEX | AF31: 41880700000001

Sheet Servicios Transporte
B2: SERVICIOS DE TRANSPORTE
B3: REF. INTERNA | C3: FECHA | D3: CLIENTE | E3: REF CLIENTE | F3: ORIGEN | G3: DESTINO | H3: COSTO
B5: SCAHT030063 | C5: 46030 | D5: AHT | E5: SOLICITUD DE SERVICIO AHT 1638 AGUA FRIA | F5: LERMA | G5: PUEBLA | H5: 11000
B6: SCAHT030064 | C6: 46038 | D6: AHT | E6: Nueva tienda WildFork CONSTITUYENTES QUERETARO (Entrega Paris) | F6: LERMA | G6: QUERÉTARO | H6: 49500
